KeyError: 'close'
Traceback:
File "/home/runner/workspace/.pythonlibs/lib/python3.11/site-packages/streamlit/runtime/scriptrunner/exec_code.py", line 121, in exec_func_with_error_handling
    result = func()
             ^^^^^^
File "/home/runner/workspace/.pythonlibs/lib/python3.11/site-packages/streamlit/runtime/scriptrunner/script_runner.py", line 593, in code_to_exec
    exec(code, module.__dict__)
File "/home/runner/workspace/app.py", line 215, in <module>
    main()
File "/home/runner/workspace/app.py", line 180, in main
    handle_backtest_button(settings["symbol"], settings["lookback_days"])
File "/home/runner/workspace/modules/ui.py", line 192, in handle_backtest_button
    backtest_result = run_backtest(selected_symbol, days=lookback_days, params=params)
                      ^^^^^^^^^^^^^^^^^^^^^^^^^^^^^^^^^^^^^^^^^^^^^^^^^^^^^^^^^^^^^^^^
File "/home/runner/workspace/modules/backtest.py", line 133, in run_backtest
    portfolio.loc[current_day, 'position_value'] = portfolio.loc[current_day, 'position'] * portfolio.loc[current_day, 'close']
                                                                                            ~~~~~~~~~~~~~^^^^^^^^^^^^^^^^^^^^^^
File "/home/runner/workspace/.pythonlibs/lib/python3.11/site-packages/pandas/core/indexing.py", line 1183, in __getitem__
    return self.obj._get_value(*key, takeable=self._takeable)
           ^^^^^^^^^^^^^^^^^^^^^^^^^^^^^^^^^^^^^^^^^^^^^^^^^^
File "/home/runner/workspace/.pythonlibs/lib/python3.11/site-packages/pandas/core/frame.py", line 4214, in _get_value
    series = self._get_item_cache(col)
             ^^^^^^^^^^^^^^^^^^^^^^^^^
File "/home/runner/workspace/.pythonlibs/lib/python3.11/site-packages/pandas/core/frame.py", line 4638, in _get_item_cache
    loc = self.columns.get_loc(item)
          ^^^^^^^^^^^^^^^^^^^^^^^^^^
File "/home/runner/workspace/.pythonlibs/lib/python3.11/site-packages/pandas/core/indexes/base.py", line 3812, in get_loc
    raise KeyError(key) from err